Workbook

Sheet OVERVIEW
A1: ARCHIPIÉLAGO - AI SUBSCRIPTION CONTROL
A3: SUSCRIPCIONES ACTIVAS
A4: Plataforma | B4: Categoría | C4: Día Renovación | D4: Costo Mensual Fijo | E4: Moneda | F4: Tarjeta | G4: Estado | H4: Correo | I4: Notas
A5: CLAUDE | B5: LLMS | C5: 16 | D5: 20 | E5: USD | F5: VISA 4237 | G5: Activa | H5: ai.lantica@lanticastudios.com
A6: TOPAZ VIDEO | B6: Ed. Img/Video | C6: 23 | D6: 33 | E6: USD | F6: VISA 4447 | G6: Activa | H6: ai.lantica@lanticastudios.com ia.gen@archipielagofilm.com
A7: MIDJOURNEY | B7: Gen. Imágenes | C7: 26 | D7: 60 | E7: USD | F7: VISA 4237 | G7: Activa | H7: arch.midjourney@gmail.com
A8: WEAVY | B8: Gen. Img/Video | C8: 26 | D8: 120 | E8: USD | F8: VISA 4237 | G8: Activa | H8: ai.management@archipielagofilm.com
A9: CAPCUT | B9: Ed. Img/Video | C9: 1 | D9: 9.99 | E9: USD | F9: VISA 4237 | G9: Activa | H9: ai.management@archipielagofilm.com | I9: *Falta la factura en el Drive, aparece como PIPO
A10: FLOW/VEO/GOOGLE ULTRA | B10: Gen. Videos | G10: Activa | H10: ai.management@archipielagofilm.com | I10: *Pago hecho por José Luis
A11: FILESTAGE | B11: Project Manag. | C11: 26 | D11: 369 | E11: USD | F11: VISA 4237 | G11: Activa | H11: ai.management@archipielagofilm.com
A12: ENHARCOR | B12: Ed. Img | C12: 30 | D12: 24 | E12: USD | F12: VISA 4447 | G12: Cancelada | H12: ai.lantica@lanticastudios.com
A13: CHATGPT | B13: LLMS | G13: Activa | H13: ia.gen@archipielagofilm.com | I13: *Pago hecho por José Luis | Pedido de cancelación 17/12/25
A14: CHATGPT | B14: LLMS | G14: Activa | H14: ai.management@archipielagofilm.com | I14: *Pago hecho por José Luis
A15: DORLABS | B15: Gen. Imágenes | C15: 17 | D15: 5.6 | E15: USD | F15: VISA 4237 | G15: Activa | H15: ia.gen@archipielagofilm.com
A16: GODADDY | B16: Dominio | G16: Activa | I16: *Pago hecho por José Luis
A19: RESUMEN MENSUAL
A20: Mes | B20: Fixed | C20: Extras | D20: One-off | E20: Total
A21: November 2025 | B21: =Nov_2025!L3 -> 606 | C21: =Nov_2025!L4 -> 5 | D21: =Nov_2025!L5 -> 0 | E21: =SUM(B21:D21) -> 611
A22: December 2025 | B22: =Dec_2025!L3 -> 551.99 | C22: =Dec_2025!L4 -> 160 | D22: =Dec_2025!L5 -> 25.6 | E22: =SUM(B22:D22) -> 737.59
A23: January 2026 | B23: =Jan_2026!L3 -> 0 | C23: =Jan_2026!L4 -> 0 | D23: =Jan_2026!L5 -> 0 | E23: =SUM(B23:D23) -> 0
A24: February 2026 | B24: =Feb_2026!L3 -> 0 | C24: =Feb_2026!L4 -> 0 | D24: =Feb_2026!L5 -> 0 | E24: =SUM(B24:D24) -> 0
A25: March 2026 | B25: =Mar_2026!L3 -> 0 | C25: =Mar_2026!L4 -> 0 | D25: =Mar_2026!L5 -> 0 | E25: =SUM(B25:D25) -> 0
A26: April 2026 | B26: =Apr_2026!L3 -> 0 | C26: =Apr_2026!L4 -> 0 | D26: =Apr_2026!L5 -> 0 | E26: =SUM(B26:D26) -> 0
A27: May 2026 | B27: =May_2026!L3 -> 0 | C27: =May_2026!L4 -> 0 | D27: =May_2026!L5 -> 0 | E27: =SUM(B27:D27) -> 0
A28: June 2026 | B28: =Jun_2026!L3 -> 0 | C28: =Jun_2026!L4 -> 0 | D28: =Jun_2026!L5 -> 0 | E28: =SUM(B28:D28) -> 0
A29: July 2026 | B29: =Jul_2026!L3 -> 0 | C29: =Jul_2026!L4 -> 0 | D29: =Jul_2026!L5 -> 0 | E29: =SUM(B29:D29) -> 0
A30: August 2026 | B30: =Aug_2026!L3 -> 0 | C30: =Aug_2026!L4 -> 0 | D30: =Aug_2026!L5 -> 0 | E30: =SUM(B30:D30) -> 0
A33: TOTALES PROYECTO
A34: Total Proyecto: | B34: =SUM(E21:E30) -> 1348.59
A35: Promedio Mensual: | B35: =AVERAGE(E21:E22) -> 674.295

Sheet Nov_2025
B1: 45962
B2: LUN | C2: MAR | D2: MIÉ | E2: JUE | F2: VIE | G2: SÁB | H2: DOM | K2: RESUMEN
G3: 1 | H3: 2 | K3: Fixed: | L3: =SUMIF(C26:C31,"Fixed",D26:D31) -> 606
K4: Extras: | L4: =SUMIF(C25:C31,"Extra",D25:AB31) -> 5
K5: One-off: | L5: =SUMIF(C26:C31,"One-off",D26:D31) -> 0
K6: TOTAL: | L6: =SUM(L3:L5) -> 611
B7: 3 | C7: 4 | D7: 5 | E7: 6 | F7: 7 | G7: 8 | H7: 9
B11: 10 | C11: 11 | D11: 12 | E11: 13 | F11: 14 | G11: 15 | H11: 16
B15: 17 | C15: 18 | D15: 19 | E15: 20 | F15: 21 | G15: 22 | H15: 23
H16: TOPAZ VIDEO $33.0
B19: 24 | C19: 25 | D19: 26 | E19: 27 | F19: 28 | G19: 29 | H19: 30
D20: MIDJOURNEY $60.0 | H20: ENHARCOR $24.0
D21: WEAVY $120.0
D22: FILESTAGE $369.0
A24: REGISTRO DE GASTOS
A25: Día | B25: Plataforma | C25: Tipo | D25: Monto | E25: Categoría | F25: Receipt | G25: Correo | H25: Usuarios | I25: Notas
A26: 23 | B26: TOPAZ VIDEO | C26: Fixed | D26: 33 | E26: Ed. Img/Video | F26: invoice | G26: ai.lantica@lanticastudios.com | H26: N/A | I26: Renovación mensual
A27: 26 | B27: MIDJOURNEY | C27: Fixed | D27: 60 | E27: Gen. Imágenes | F27: invoice | G27: arch.midjourney@gmail.com | H27: N/A | I27: Suscripción inicial
A28: 26 | B28: WEAVY | C28: Fixed | D28: 120 | E28: Gen. Img/Video | F28: receipt | G28: ai.management@archipielagofilm.com | H28: N/A | I28: Suscripción inicial
A29: 26 | B29: FILESTAGE | C29: Fixed | D29: 369 | E29: Project Manag. | F29: factura | G29: ai.management@archipielagofilm.com | H29: N/A | I29: Suscripción inicial
A30: 27 | B30: CLAUDE | C30: Extra | D30: 5 | E30: Modelo LLM | F30: receipt | G30: ai.lantica@lanticastudios.com | H30: N/A | I30: Créditos extra
A31: 30 | B31: ENHARCOR | C31: Fixed | D31: 24 | E31: Ed. Img | F31: receipt | G31: ai.lantica@lanticastudios.com | H31: N/A | I31: Renovación mensual

Sheet Dec_2025
B1: DECEMBER 2025
B2: LUN | C2: MAR | D2: MIÉ | E2: JUE | F2: VIE | G2: SÁB | H2: DOM | K2: RESUMEN
B3: 1 | C3: 2 | D3: 3 | E3: 4 | F3: 5 | G3: 6 | H3: 7 | K3: Fixed: | L3: =SUMIF(C28:C50,"Fixed",D28:D50) -> 551.99
B4: CAPCUT $9.99 | D4: CLAUDE EXTRA $5 | E4: CLAUDE EXTRA $5 | F4: CLAUDE EXTRA $5 | K4: Extras: | L4: =SUMIF(C28:C50,"Extra",D28:D50) -> 160
K5: One-off: | L5: =SUMIF(C28:C50,"One-off",D28:D50) -> 25.6
K6: TOTAL: | L6: =SUM(L3:L5) -> 737.59
B7: 8 | C7: 9 | D7: 10 | E7: 11 | F7: 12 | G7: 13 | H7: 14
E8: WEAVY EXTRA $50 | G8: CLAUDE EXTRA $15
B11: 15 | C11: 16 | D11: 17 | E11: 18 | F11: 19 | G11: 20 | H11: 21
B12: CLAUDE EXTRA $5 | C12: CLAUDE $20.0 | D12: WEAVY EXTRA $50 | E12: CLAUDE EXTRA $10
C13: CLAUDE EXTRA $5 | D13: FAL $20.0
D14: CLAUDE EXTRA $5
D15: CLAUDE EXTRA $5
D16: DORLABS $5.60
B17: 22 | C17: 23 | D17: 24 | E17: 25 | F17: 26 | G17: 27 | H17: 28
C18: TOPAZ VIDEO $33.0 | F18: WEAVY $120.0
F19: FILESTAGE $369.0
B21: 29 | C21: 30 | D21: 31
C22: ENHARCOR $24.0
A26: REGISTRO DE GASTOS
A27: Día | B27: Plataforma | C27: Tipo | D27: Monto | E27: Categoría | F27: Receipt | G27: Correo | H27: Usuarios | I27: Notas
A28: 1 | B28: CAPCUT | C28: Fixed | D28: 9.99 | E28: Ed. Video | G28: ai.management@archipielagofilm.com | H28: N/A | I28: Suscripción inicial
A29: 3 | B29: CLAUDE | C29: Extra | D29: 5 | E29: LLMS | F29: receipt | G29: ai.lantica@lanticastudios.com | H29: N/A | I29: Créditos extra
A30: 4 | B30: CLAUDE | C30: Extra | D30: 5 | E30: LLMS | F30: receipt | G30: ai.lantica@lanticastudios.com | H30: N/A | I30: Créditos extra
A31: 5 | B31: CLAUDE | C31: Extra | D31: 5 | E31: LLMS | F31: receipt | G31: ai.lantica@lanticastudios.com | H31: N/A | I31: Créditos extra
A32: 10 | B32: CLAUDE | C32: Extra | D32: 10 | E32: LLMS | F32: receipt | G32: ai.lantica@lanticastudios.com | H32: N/A | I32: Créditos extra
A33: 11 | B33: WEAVY | C33: Extra | D33: 50 | E33: Gen. Img/Video | F33: receipt | G33: ai.management@archipielagofilm.com | H33: ia.gen@archipielagofilm.com | I33: Créditos extra
A34: 13 | B34: CLAUDE | C34: Extra | D34: 15 | E34: LLMS | F34: receipt | G34: ai.lantica@lanticastudios.com | H34: N/A | I34: Créditos extra
A35: 15 | B35: CLAUDE | C35: Extra | D35: 5 | E35: LLMS | F35: receipt | G35: ai.lantica@lanticastudios.com | H35: N/A | I35: Créditos extra
A36: 16 | B36: CLAUDE | C36: Extra | D36: 5 | E36: LLMS | F36: receipt | G36: ai.lantica@lanticastudios.com | H36: N/A | I36: Créditos extra
A37: 16 | B37: CLAUDE | C37: Fixed | D37: 20 | E37: LLMS | F37: receipt | G37: ai.management@archipielagofilm.com | H37: N/A | I37: Renovación mensual
A38: 17 | B38: CLAUDE | C38: Extra | D38: 5 | E38: LLMS | F38: receipt | G38: ai.lantica@lanticastudios.com | H38: N/A | I38: Créditos extra
A39: 17 | B39: CLAUDE | C39: Extra | D39: 5 | E39: LLMS | F39: receipt | G39: ai.lantica@lanticastudios.com | H39: N/A | I39: Créditos extra
A40: 17 | B40: WEAVY | C40: Extra | D40: 50 | E40: Gen. Img/Video | F40: receipt | G40: ai.management@archipielagofilm.com | H40: ia.gen@archipielagofilm.com | I40: Créditos extra
A41: 17 | B41: FAL | C41: One-off | D41: 20 | E41: Gen. Img/Video | F41: receipt | G41: ia.gen@archipielagofilm.com | H41: N/A | I41: Compra de créditos
A42: 17 | B42: DORLABS | C42: One-off | D42: 5.6 | E42: Gen. Imágenes | F42: receipt | G42: ia.gen@archipielagofilm.com | H42: N/A
A43: 23 | B43: TOPAZ | C43: Fixed | D43: 33 | E43: Upscale | G43: ai.lantica@lanticastudios.com | H43: N/A
A44: 26 | B44: MIDJOURNEY | C44: Fixed | D44: 0 | E44: Gen. Imágenes | G44: arch.midjourney@gmail.com | H44: N/A | I44: Cancelado
A45: 26 | B45: WEAVY | C45: Fixed | D45: 120 | E45: Gen. Img/Video | G45: ai.management@archipielagofilm.com | H45: ia.gen@archipielagofilm.com | I45: Renovación mensual
A46: 26 | B46: FILESTAGE | C46: Fixed | D46: 369 | E46: Project Manag. | G46: ai.management@archipielagofilm.com | H46: N/A | I46: Renovación mensual
...

Sheet Jan_2026
B1: 46023 | K1: RESUMEN
B2: LUN | C2: MAR | D2: MIÉ | E2: JUE | F2: VIE | G2: SÁB | H2: DOM | K2: Fixed: | L2: =SUMIF(C26:C49,"Fixed",D28:D49) -> 0
E3: 1 | F3: 2 | G3: 3 | H3: 4 | K3: Extras: | L3: =SUMIF(C26:C49,"Extra",D28:D49) -> 0
K4: One-off: | L4: =SUMIF(C26:C49,"One-off",D28:D49) -> 0
K5: TOTAL: | L5: =SUM(L2:L4) -> 0
B7: 5 | C7: 6 | D7: 7 | E7: 8 | F7: 9 | G7: 10 | H7: 11
B11: 12 | C11: 13 | D11: 14 | E11: 15 | F11: 16 | G11: 17 | H11: 18
B15: 19 | C15: 20 | D15: 21 | E15: 22 | F15: 23 | G15: 24 | H15: 25
B19: 26 | C19: 27 | D19: 28 | E19: 29 | F19: 30 | G19: 31
A24: REGISTRO DE GASTOS
A25: Día | B25: Plataforma | C25: Tipo | D25: Monto | E25: Categoría | F25: Receipt | G25: Correo | H25: Usuarios | I25: Notas

Sheet Feb_2026
B1: FEBRUARY 2026 | K1: RESUMEN
B2: LUN | C2: MAR | D2: MIÉ | E2: JUE | F2: VIE | G2: SÁB | H2: DOM | K2: Fixed: | L2: =SUMIF(C25:C42,"Fixed",D25:D42) -> 0
H3: 1 | K3: Extras: | L3: =SUMIF(C26:C42,"Extra",D26:D42) -> 0
K4: One-off: | L4: =SUMIF(C26:C42,"One-off",D26:D42) -> 0
K5: TOTAL: | L5: =SUM(L2:L4) -> 0
B7: 2 | C7: 3 | D7: 4 | E7: 5 | F7: 6 | G7: 7 | H7: 8
B11: 9 | C11: 10 | D11: 11 | E11: 12 | F11: 13 | G11: 14 | H11: 15
B15: 16 | C15: 17 | D15: 18 | E15: 19 | F15: 20 | G15: 21 | H15: 22
B19: 23 | C19: 24 | D19: 25 | E19: 26 | F19: 27 | G19: 28
A24: REGISTRO DE GASTOS
A25: Día | B25: Plataforma | C25: Tipo | D25: Monto | E25: Categoría | F25: Receipt | G25: Correo | H25: Usuario | I25: Notas

Sheet Mar_2026
B1: 46082 | K1: RESUMEN
B2: LUN | C2: MAR | D2: MIÉ | E2: JUE | F2: VIE | G2: SÁB | H2: DOM | K2: Fixed: | L2: =SUMIF(C29:C45,"Fixed",D29:D45) -> 0
H3: 1 | K3: Extras: | L3: =SUMIF(C30:C46,"Extra",D30:D46) -> 0
K4: One-off: | L4: =SUMIF(C30:C46,"One-off",D30:D46) -> 0
K5: TOTAL: | L5: =SUM(L2:L4) -> 0
B7: 2 | C7: 3 | D7: 4 | E7: 5 | F7: 6 | G7: 7 | H7: 8
B11: 9 | C11: 10 | D11: 11 | E11: 12 | F11: 13 | G11: 14 | H11: 15
B15: 16 | C15: 17 | D15: 18 | E15: 19 | F15: 20 | G15: 21 | H15: 22
B19: 23 | C19: 24 | D19: 25 | E19: 26 | F19: 27 | G19: 28 | H19: 29
B23: 30 | C23: 31
A28: REGISTRO DE GASTOS
A29: Día | B29: Plataforma | C29: Tipo | D29: Monto | E29: Categoría | F29: Receipt | G29: Correo | H29: Usuarios | I29: Notas

Sheet Apr_2026
B1: 46113 | K1: RESUMEN
B2: LUN | C2: MAR | D2: MIÉ | E2: JUE | F2: VIE | G2: SÁB | H2: DOM | K2: Fixed: | L2: =SUMIF(C25:C42,"Fixed",D25:D42) -> 0
D3: 1 | E3: 2 | F3: 3 | G3: 4 | H3: 5 | K3: Extras: | L3: =SUMIF(C26:C42,"Extra",D26:D42) -> 0
K4: One-off: | L4: =SUMIF(C26:C42,"One-off",D26:D42) -> 0
K5: TOTAL: | L5: =SUM(L2:L4) -> 0
B7: 6 | C7: 7 | D7: 8 | E7: 9 | F7: 10 | G7: 11 | H7: 12
B11: 13 | C11: 14 | D11: 15 | E11: 16 | F11: 17 | G11: 18 | H11: 19
B15: 20 | C15: 21 | D15: 22 | E15: 23 | F15: 24 | G15: 25 | H15: 26
B19: 27 | C19: 28 | D19: 29 | E19: 30
A24: REGISTRO DE GASTOS
A25: Día | B25: Plataforma | C25: Tipo | D25: Monto | E25: Categoría | F25: Receipt | G25: Correo | H25: Usuarios | I25: Notas

Sheet May_2026
B1: 46143 | K1: RESUMEN
B2: LUN | C2: MAR | D2: MIÉ | E2: JUE | F2: VIE | G2: SÁB | H2: DOM | K2: Fixed: | L2: =SUMIF(C25:C41,"Fixed",D25:D41) -> 0
F3: 1 | G3: 2 | H3: 3 | K3: Extras: | L3: =SUMIF(C26:C42,"Extra",D26:D42) -> 0
K4: One-off: | L4: =SUMIF(C26:C42,"One-off",D26:D42) -> 0
K5: TOTAL: | L5: =SUM(L2:L4) -> 0
B7: 4 | C7: 5 | D7: 6 | E7: 7 | F7: 8 | G7: 9 | H7: 10
B11: 11 | C11: 12 | D11: 13 | E11: 14 | F11: 15 | G11: 16 | H11: 17
B15: 18 | C15: 19 | D15: 20 | E15: 21 | F15: 22 | G15: 23 | H15: 24
B19: 25 | C19: 26 | D19: 27 | E19: 28 | F19: 29 | G19: 30 | H19: 31
A24: REGISTRO DE GASTOS
A25: Día | B25: Plataforma | C25: Tipo | D25: Monto | E25: Categoría | F25: Receipt | G25: Correo | H25: Usuarios | I25: Notas

Sheet Jun_2026
B1: 46174 | K1: RESUMEN
B2: LUN | C2: MAR | D2: MIÉ | E2: JUE | F2: VIE | G2: SÁB | H2: DOM | K2: Fixed: | L2: =SUMIF(C25:C41,"Fixed",D25:D41) -> 0
B3: 1 | C3: 2 | D3: 3 | E3: 4 | F3: 5 | G3: 6 | H3: 7 | K3: Extras: | L3: =SUMIF(C26:C42,"Extra",D26:D42) -> 0
K4: One-off: | L4: =SUMIF(C26:C42,"One-off",D26:D42) -> 0
K5: TOTAL: | L5: =SUM(L2:L4) -> 0
B7: 8 | C7: 9 | D7: 10 | E7: 11 | F7: 12 | G7: 13 | H7: 14
B11: 15 | C11: 16 | D11: 17 | E11: 18 | F11: 19 | G11: 20 | H11: 21
B15: 22 | C15: 23 | D15: 24 | E15: 25 | F15: 26 | G15: 27 | H15: 28
B19: 29 | C19: 30
A24: REGISTRO DE GASTOS
A25: Día | B25: Plataforma | C25: Tipo | D25: Monto | E25: Categoría | F25: Receipt | G25: Correo | H25: Usuarios | I25: Notas

Sheet Jul_2026
B1: 46204 | K1: RESUMEN
B2: LUN | C2: MAR | D2: MIÉ | E2: JUE | F2: VIE | G2: SÁB | H2: DOM | K2: Fixed: | L2: =SUMIF(C26:C42,"Fixed",D26:D42) -> 0
D3: 1 | E3: 2 | F3: 3 | G3: 4 | H3: 5 | K3: Extras: | L3: =SUMIF(C26:C42,"Extra",D26:D42) -> 0
K4: One-off: | L4: =SUMIF(C26:C42,"One-off",D26:D42) -> 0
K5: TOTAL: | L5: =SUM(L2:L4) -> 0
B7: 6 | C7: 7 | D7: 8 | E7: 9 | F7: 10 | G7: 11 | H7: 12
B11: 13 | C11: 14 | D11: 15 | E11: 16 | F11: 17 | G11: 18 | H11: 19
B15: 20 | C15: 21 | D15: 22 | E15: 23 | F15: 24 | G15: 25 | H15: 26
B19: 27 | C19: 28 | D19: 29 | E19: 30 | F19: 31
A24: REGISTRO DE GASTOS
A25: Día | B25: Plataforma | C25: Tipo | D25: Monto | E25: Categoría | F25: Receipt | G25: Correo | H25: Usuarios | I25: Notas

Sheet Aug_2026
B1: 46235 | K1: RESUMEN
B2: LUN | C2: MAR | D2: MIÉ | E2: JUE | F2: VIE | G2: SÁB | H2: DOM | K2: Fixed: | L2: =SUMIF(C30:C45,"Fixed",D30:D45) -> 0
G3: 1 | H3: 2 | K3: Extras: | L3: =SUMIF(C30:C46,"Extra",D30:D46) -> 0
K4: One-off: | L4: =SUMIF(C30:C46,"One-off",D30:D46) -> 0
K5: TOTAL: | L5: =SUM(L2:L4) -> 0
B7: 3 | C7: 4 | D7: 5 | E7: 6 | F7: 7 | G7: 8 | H7: 9
B11: 10 | C11: 11 | D11: 12 | E11: 13 | F11: 14 | G11: 15 | H11: 16
B15: 17 | C15: 18 | D15: 19 | E15: 20 | F15: 21 | G15: 22 | H15: 23
B19: 24 | C19: 25 | D19: 26 | E19: 27 | F19: 28 | G19: 29 | H19: 30
B23: 31
A28: REGISTRO DE GASTOS
A29: Día | B29: Plataforma | C29: Tipo | D29: Monto | E29: Categoría | F29: Receipt | G29: Correo | H29: Usuarios | I29: Notas
